<?xml version="1.0"?>
<robot name="arms">
	<link name = "left_forearm">
		<visual>
			<geometry>
				<box size="0.15  0.03  0.03"/>
			</geometry>
			<origin rpy="0 0 0" xyz="0.075 0 0"/>
		</visual>
		<inertial>
		  <mass value="10"/>
		  <inertia ixx="0.001" ixy="0.001" ixz="0.001" iyy="0.001" iyz="0.001" izz="0.001"/>
		</inertial>
	</link>
	<link name = "left_backarm">
		<visual>
			<geometry>
				<box size="0.15  0.03  0.03"/>
			</geometry>
			<origin rpy="0 0 0" xyz="0.075 0 0"/>
		</visual>
		<inertial>
		  <mass value="10"/>
		  <inertia ixx="0.001" ixy="0.001" ixz="0.001" iyy="0.001" iyz="0.001" izz="0.001"/>
		</inertial>
	</link>
	<link name = "right_forearm">
		<visual>
			<geometry>
				<box size="0.15  0.03  0.03"/>
			</geometry>
			<origin rpy="0 0 0" xyz="0.075  0  0"/>
		</visual>
		<inertial>
		  <mass value="10"/>
		  <inertia ixx="0.001" ixy="0.001" ixz="0.001" iyy="0.001" iyz="0.001" izz="0.001"/>
		</inertial>
	</link>
	<link name = "right_backarm">
		<visual>
			<geometry>
				<box size="0.15  0.03  0.03"/>
			</geometry>
			<origin rpy="0 0 0" xyz="0.075 0 0"/>
		</visual>
		<inertial>
		  <mass value="10"/>
		  <inertia ixx="0.001" ixy="0.001" ixz="0.001" iyy="0.001" iyz="0.001" izz="0.001"/>
		</inertial>
	</link>
	<link name = "base_link">
		<visual>
			<geometry>
				<box size="0.06  0.14  0.03"/>
			</geometry>
			<origin rpy="0 0 0" xyz="-0.03  0  0"/>
		</visual>
		<inertial>
		  <mass value="10"/>
		  <inertia ixx="0.001" ixy="0.001" ixz="0.001" iyy="0.001" iyz="0.001" izz="0.001"/>
		</inertial>
	</link>
	<link name = "left_fingers">
		<visual>
			<geometry>
				<box size="0.03  0.01  0.03"/>
			</geometry>
			<origin rpy="0 0 0" xyz="0.015  0  0"/>
		</visual>
		<inertial>
		  <mass value="10"/>
		  <inertia ixx="0.001" ixy="0.001" ixz="0.001" iyy="0.001" iyz="0.001" izz="0.001"/>
		</inertial>
	</link>
	<link name = "left_thumb">
		<visual>
			<geometry>
				<box size="0.03  0.01  0.03"/>
			</geometry>
			<origin rpy="0 0 0" xyz="0.015  0  0"/>
		</visual>
		<inertial>
		  <mass value="10"/>
		  <inertia ixx="0.001" ixy="0.001" ixz="0.001" iyy="0.001" iyz="0.001" izz="0.001"/>
		</inertial>
	</link>
	<link name = "right_fingers">
		<visual>
			<geometry>
				<box size="0.03  0.01  0.03"/>
			</geometry>
			<origin rpy="0 0 0" xyz="0.015  0  0"/>
		</visual>
		<inertial>
		  <mass value="10"/>
		  <inertia ixx="0.001" ixy="0.001" ixz="0.001" iyy="0.001" iyz="0.001" izz="0.001"/>
		</inertial>
	</link>
	<link name = "right_thumb">
		<visual>
			<geometry>
				<box size="0.03  0.01  0.03"/>
			</geometry>
			<origin rpy="0 0 0" xyz="0.015  0  0"/>
		</visual>
		<inertial>
		  <mass value="10"/>
		  <inertia ixx="0.001" ixy="0.001" ixz="0.001" iyy="0.001" iyz="0.001" izz="0.001"/>
		</inertial>
	</link>
	<link name = "left_wrist">
		<visual>
			<geometry>
				<box size="0.03  0.03  0.03"/>
			</geometry>
			<origin rpy="0 0 0" xyz="0.015 0 0"/>
		</visual>
		<inertial>
		  <mass value="10"/>
		  <inertia ixx="0.001" ixy="0.001" ixz="0.001" iyy="0.001" iyz="0.001" izz="0.001"/>
		</inertial>
	</link>
	<link name = "right_wrist">
		<visual>
			<geometry>
				<box size="0.03  0.03  0.03"/>
			</geometry>
			<origin rpy="0 0 0" xyz="0.015 0 0"/>
		</visual>
		<inertial>
		  <mass value="10"/>
		  <inertia ixx="0.001" ixy="0.001" ixz="0.001" iyy="0.001" iyz="0.001" izz="0.001"/>
		</inertial>
	</link>
	<joint name="right_shoulder" type="revolute">
		<axis xyz="0 0 1"/>
		<limit effort="1000.0" lower="-0.6" upper="0.6" velocity="0.5"/>
		<parent link="base_link"/>
		<child link="right_backarm"/>
		<origin xyz="0 -0.07 0"/>
	</joint>
	<joint name="left_shoulder" type="revolute">
		<axis xyz="0 0 1"/>
		<limit effort="1000.0" lower="-0.6" upper="0.6" velocity="0.5"/>
		<parent link="base_link"/>
		<child link="left_backarm"/>
		<origin xyz="0 0.07 0"/>
	</joint>
	<joint name="right_elbow" type="revolute">
		<axis xyz="0 0 1"/>
		<limit effort="1000.0" lower="-0.8" upper="0.8" velocity="0.5"/>
		<parent link="right_backarm"/>
		<child link="right_forearm"/>
		<origin xyz="0.15 0 0"/>
	</joint>
	<joint name="left_elbow" type="revolute">
		<axis xyz="0 0 1"/>
		<limit effort="1000.0" lower="-0.8" upper="0.8" velocity="0.5"/>
		<parent link="left_backarm"/>
		<child link="left_forearm"/>
		<origin xyz="0.15 0 0"/>
	</joint>
	<joint name="left_wrist_joint" type="revolute">
		<axis xyz="0 0 1"/>
		<limit effort="1000.0" lower="-0.8" upper="0.2" velocity="0.5"/>
		<parent link="left_forearm"/>
		<child link="left_wrist"/>
		<origin xyz="0.15 0 0"/>
	</joint>
	<joint name="right_wrist_joint" type="revolute">
		<axis xyz="0 0 1"/>
		<limit effort="1000.0" lower="-0.2" upper="0.8" velocity="0.5"/>
		<parent link="right_forearm"/>
		<child link="right_wrist"/>
		<origin xyz="0.15 0 0"/>
	</joint>
	<joint name="right_finger_joint" type="prismatic">
		<axis xyz="0 1 0"/>
		<limit effort="1000.0" lower="0" upper="0.03" velocity="0.5"/>
		<parent link="right_wrist"/>
		<child link="right_fingers"/>
		<origin xyz="0.03 -0.015 0"/>
	</joint>
	<joint name="left_finger_joint" type="prismatic">
		<axis xyz="0 1 0"/>
		<limit effort="1000.0" lower="-0.02" upper="0.0" velocity="0.5"/>
		<parent link="left_wrist"/>
		<child link="left_fingers"/>
		<origin xyz="0.03 0.015 0"/>
	</joint>
	<joint name="right_thumb_joint" type="revolute">
		<axis xyz="0 1 0"/>
		<limit effort="1000.0" lower="-0.3" upper="0.3" velocity="0.5"/>
		<parent link="right_wrist"/>
		<child link="right_thumb"/>
		<origin xyz="0.03 0 0"/>
	</joint>
	<joint name="left_thumb_joint" type="revolute">
		<axis xyz="0 1 0"/>
		<limit effort="1000.0" lower="-0.3" upper="0.3" velocity="0.5"/>
		<parent link="left_wrist"/>
		<child link="left_thumb"/>
		<origin xyz="0.03 -0.015 0"/>
	</joint>
	<gazebo>
		<plugin name="gazebo_ros_control" filename="libgazebo_ros_control.so">
			<robotNamespace>/</robotNamespace>
		</plugin>
	</gazebo>
</robot>
